Workbook

Sheet 三星词频（带音标与简明义项）
A1: # | B1: 单词 | C1: 解释
A2: 1 | B2: register | C2: =VLOOKUP(B2,Sheet2!$A:$B,2,0) -> /'redʒɪstə//'rɛdʒɪstɚ/ - vt. 记录；注册；登记；把…挂号；挂号邮寄；正式提出 - vi. 登记；注册；挂号 - n. 注册；登记簿；登记；记录；寄存器 时 态: registered, registering, registers 名 词: registerer 形容词: registrable...
A3: 2 | B3: somewhere | C3: =VLOOKUP(B3,Sheet2!$A:$B,2,0) -> /'sʌmweə//'sʌmwɛr/ adv. 某处,在某处
A4: 3 | B4: stupid | C4: =VLOOKUP(B4,Sheet2!$A:$B,2,0) -> /'stjuːpɪd//'stupɪd/ - adj. 愚蠢的；麻木的；乏味的 - n. 傻瓜，笨蛋 比较级: stupider, stupidest 副 词: stupidly 名 词: stupidness
A5: 4 | B5: mystery | C5: =VLOOKUP(B5,Sheet2!$A:$B,2,0) -> /'mɪst(ə)rɪ//'mɪstri/ - n. 神秘(性), 秘密(性) - 神秘的事, 难以理解的事物 - 来历不明[难探究竟]的人
A6: 5 | B6: crucial | C6: =VLOOKUP(B6,Sheet2!$A:$B,2,0) -> /'kruːʃ(ə)l//'krʊʃəl/ adj. 决定性的；重要的；定局的；决断的 副 词: crucially
A7: 6 | B7: construction | C7: =VLOOKUP(B7,Sheet2!$A:$B,2,0) -> /kən'strʌkʃ(ə)n//kən'strʌkʃən/ - n. 建造, 建设; 建筑业 - 建造物, 建筑物 - 解释, 意思 - 结构, 句法关系 形容词: constructional 副 词: constructionally...
A8: 7 | B8: lie | C8: =VLOOKUP(B8,Sheet2!$A:$B,2,0) -> /laɪ//li/ - vi. 躺, 卧 - 位于 - 展现, 伸展 - 说谎 - vi. & link v. 平放 - n. 谎话 LIE液体离子蒸发 时 态: lay lain lying lies
A9: 8 | B9: inning | C9: =VLOOKUP(B9,Sheet2!$A:$B,2,0) -> /'ɪnɪŋ//'ɪnɪŋ/ n. （棒球的）一局；（荒地等的）围垦；执政期；轮到显身手的机会
A10: 9 | B10: mate | C10: =VLOOKUP(B10,Sheet2!$A:$B,2,0) -> /meɪt//met/ - n. 同事；助手，大副；配偶；配对物 - vt. 使配对；结伴；使一致 - vi. 成配偶；交配；紧密配合 MATEabbr. Machine-Aided Translation Editing 机器辅助转换编辑 时 态: mated, mating, mates...
A11: 10 | B11: ski | C11: =VLOOKUP(B11,Sheet2!$A:$B,2,0) -> /skiː//ski/ - n. 滑雪橇 - vi. 滑雪 - adj. 滑雪（用）的 SKIabbr. Spending the Kids' Inheritance “花掉给子女的遗产”(指那些不给子女留遗产,选择尽情享用自己劳苦半生得来的财富的五十来岁的人) SKIabbr. Spending the Kids' Inheritance “花掉给子女的遗产”（指那些不给子女留遗产，选择尽情享用自己劳苦半生得来的财富的五十来岁的人） 形容词: skiable 名 词: skier...
A12: 11 | B12: communication | C12: =VLOOKUP(B12,Sheet2!$A:$B,2,0) -> /kəmjuːnɪ'keɪʃ(ə)n//kə,mjunɪ'keʃən/ - n. 交流, 交际, 通讯 - 信息, 消息 - 通信工具, 交通联系 形容词: communicational
A13: 12 | B13: technical | C13: =VLOOKUP(B13,Sheet2!$A:$B,2,0) -> /'teknɪk(ə)l//'tɛknɪkl/ - adj. 技术的; 应用科学的 - 艺术的, 工艺的 - (指书等)要求有专门知识的, 使用术语的, 专业的 副 词: technically 名 词: technicalness...
... A1485: 1484 | B1485: observer | C1485: =VLOOKUP(B1485,Sheet2!$A:$B,2,0) -> /əb'zɜːvə//əb'zɝvɚ/ n. 观察者, 观察员; 遵守者

Sheet sheet1
A1: wheel | B1: n.轮, 车轮, 轮子
A2: viewer | B2: n.电视观众,阅读器
A3: layer | B3: n.层, 阶层
A4: faith | B4: n.信任, 信念, 宗教信仰, 忠实, 保证, 诺言, 约定
A5: racial | B5: adj.人种的, 种族的, 种族间的
A6: folk | B6: n.人们, 亲属(复数), 民族
A7: exhaust | B7: vt.用尽, 耗尽, 抽完, 使精疲力尽
A8: knock | B8: v.敲, 敲打, 敲击, (使)碰撞
A9: flee | B9: vt.逃避, 逃跑, 逃走
A10: dancing | B10: n.舞蹈
A11: accommodation | B11: n.住处, 膳宿, (车, 船, 飞机等的)预定铺位, (眼睛等的)适应性调节, (社会集团间的)迁就融合
A12: access | B12: n.通路, 访问, 入门
... A383: proportion | B383: n.比例, 均衡, 面积, 部分
A384: inch | B384: n.英寸(=1 | C384: 12英尺)
A385: homosexual | B385: adj.同性恋的
A386: overwhelming | B386: adj.压倒性的, 无法抵抗的
A387: pension | B387: n.养老金, 退休金
A388: surgery | B388: n.外科, 外科学, 手术室, 诊疗室
A389: tackle | B389: n.工具, 复滑车, 滑车, 辘轱, 用具, 装备, 扭倒
A390: mental | B390: adj.精神的, 智力的
A391: given | B391: adj.赠予的, 沉溺的, 特定的, 假设的
A392: presumably | B392: adv.推测起来, 大概
A393: shaped | B393: vbl.成形,发展
A394: opposite | B394: adj.相对的, 对面的, 对立的, 相反的, 对等的, 对应的
A395: pub | B395: n.酒馆, 客栈
A396: percentage | B396: n.百分数, 百分率, 百分比
... A536: blast | B536: n.一阵(风), 一股(气流), 爆炸, 冲击波
A537: inform | B537: v.(～ of | C537: about) 通知, 告诉, 获悉, 告知
A538: equally | B538: adv.相等地, 平等地, 公平地
A539: glance | B539: vi.扫视, 匆匆一看
A540: tale | B540: n.故事, 坏话, 流言蜚语, 谣言, 叙述, 传说
A541: philosophy | B541: n.哲学, 哲学体系, 达观, 冷静
A542: loud | B542: adj.高声的, 不断的, 喧吵的
A543: grab | B543: v.抢夺, 攫取, 夺取
A544: entertainment | B544: n.款待, 娱乐, 娱乐表演
A545: bath | B545: n. 沐浴；浴室；浴盆 v. 洗澡
A546: planet | B546: n.〖天〗行星
A547: sail | B547: v.航行(于)
A548: pet | B548: n.宠物, 受宠爱的人, 不悦
A549: port | B549: n.港口, 舱门, 左舷, 避风港, 枪眼
...

Sheet Sheet2
A1: 单词 | B1: 解释
A2: exposure | B2: /ɪk'spəʊʒə//ɪk'spoʒɚ/ - n. 暴露, 显露 - 揭发, 揭露 - (软片等)曝光
A3: raid | B3: /reɪd//red/ - n. 袭击；突袭；搜捕；抢劫 - vi. 对…进行突然袭击 - vt. 袭击，突袭 RAID磁盘冗余阵列 时 态: raided, raiding, raids 名 词: raider
A4: destruction | B4: /dɪ'strʌkʃ(ə)n//dɪ'strʌkʃən/ n. 破坏, 毁灭, 消灭
A5: guitar | B5: /gɪ'tɑː//ɡɪ'tɑr/ n. 吉他, 六弦琴 名 词: guitarist
A6: dig | B6: /dɪg//dɪɡ/ - vt. 挖，掘；探究 - vi. 挖掘 - n. 戳，刺；挖苦 DIGabbr. Deputy Inspector-General 副监察长 时 态: dug digging, digs
A7: inning | B7: /'ɪnɪŋ//'ɪnɪŋ/ n. （棒球的）一局；（荒地等的）围垦；执政期；轮到显身手的机会
A8: script | B8: /skrɪpt//skrɪpt/ - n. 手迹；脚本；书写用的字母 - vt. 把…改编为剧本 - vi. 写电影脚本 时 态: scripted, scripting, scripts
A9: crucial | B9: /'kruːʃ(ə)l//'krʊʃəl/ adj. 决定性的；重要的；定局的；决断的 副 词: crucially
A10: exception | B10: /ɪk'sepʃ(ə)n//ɪk'sɛpʃən/ n. 例外
A11: mate | B11: /meɪt//met/ - n. 同事；助手，大副；配偶；配对物 - vt. 使配对；结伴；使一致 - vi. 成配偶；交配；紧密配合 MATEabbr. Machine-Aided Translation Editing 机器辅助转换编辑 时 态: mated, mating, mates...
A12: definitely | B12: /'dɛfɪnətli/ - adv. 明确地, 确切地 - 一定地, 肯定地
... A1483: well-known | B1483: /'wel'nəʊn//'wɛl'non / adj. 出名的, 众所周知的; 熟悉的
