Workbook

Sheet 二星词频（带音标与简明义项）
A1: # | B1: 单词 | C1: 解释
A2: 1 | B2: sour | C2: =VLOOKUP(B2,Sheet1!$A:$B,2,0) -> /saʊə//'saʊɚ/ - adj. 有酸味的, 酸的 - 有发酵味道的, 酸腐的, 馊的 - 坏脾气的; 别扭的 - vt. & vi. (使某物)变酸, 变馊; (使某人)阴郁 比较级: sourer, sourest 形容词: sourish 副 词: sourly 名 词: sourness...
A3: 2 | B3: freely | C3: =VLOOKUP(B3,Sheet1!$A:$B,2,0) -> /ˈfri:lɪ//'frili/ adv. 自由地,随意地,免费地
A4: 3 | B4: educated | C4: =VLOOKUP(B4,Sheet1!$A:$B,2,0) -> /'edjʊkeɪtɪd//'ɛdʒə'ketɪd/ - adj. 有教养的；受过教育的 - v. 教导；训练；培育（educate的过去分词形式）
A5: 4 | B5: engaged | C5: =VLOOKUP(B5,Sheet1!$A:$B,2,0) -> /ɪn'geɪdʒd//ɪn'gedʒd/ - adj. 使用中的，忙碌的 - v. 约定；保证；同…订婚（engage的过去分词）
A6: 5 | B6: prohibit | C6: =VLOOKUP(B6,Sheet1!$A:$B,2,0) -> /prə(ʊ)'hɪbɪt//prə'hɪbɪt/ vt. 阻止，禁止 时 态: prohibited, prohibiting, prohibits
A7: 6 | B7: tan | C7: =VLOOKUP(B7,Sheet1!$A:$B,2,0) -> /tæn//tæn/ - n. 黄褐色, 棕黄色 - vt. & vi. (使)晒成棕褐色 - vt. 硝制(皮革) TANabbr. total ammonia nitrogen 总氨氮 时 态: tanned, tanning, tans 形容词: tannish...
A8: 7 | B8: dispose | C8: =VLOOKUP(B8,Sheet1!$A:$B,2,0) -> /dɪ'spəʊz//dɪ'spoz/ - vt. 处理；处置；安排 - vi. 处理；安排；（能够）决定 - n. 处置；性情 时 态: disposed, disposing, disposes 名 词: disposer
A9: 8 | B9: voyage | C9: =VLOOKUP(B9,Sheet1!$A:$B,2,0) -> /'vɒɪɪdʒ//'vɔɪɪdʒ/ - n. 航行；航程；旅行记 - vi. 航海；航行 - vt. 飞过；渡过 时 态: voyaged, voyaging, voyages 名 词: voyager
A10: 9 | B10: doll | C10: =VLOOKUP(B10,Sheet1!$A:$B,2,0) -> /dɔl//dɑl/ - n. 洋娃娃；玩偶；无头脑的美丽女人 - vt. 把…打扮得花枝招展 Doll多尔(女子名, Dorothy 的昵称)
A11: 10 | B11: copper | C11: =VLOOKUP(B11,Sheet1!$A:$B,2,0) -> /'kɒpə//'kɑpɚ/ - n. 铜；铜币；[俚]警察 - adj. 铜的 - vt. 镀铜于 时 态: coppered, coppering, coppers 形容词: coppery
A12: 11 | B12: obsession | C12: =VLOOKUP(B12,Sheet1!$A:$B,2,0) -> /əb'seʃ(ə)n//əbˈsɛʃən/ n. 困扰, 无法摆脱的思想(或情感) 形容词: obsessional 副 词: obsessionally
A13: 12 | B13: leaflet | C13: =VLOOKUP(B13,Sheet1!$A:$B,2,0) -> /'liːflɪt//'liflət/ n. 传单, 散页印刷品 时 态: leafletedalso leafletted leafletingleafletting leafletsleaflets
... A148: 147 | B148: penis | C148: =VLOOKUP(B148,Sheet1!$A:$B,2,0) -> /'piːnɪs//'pinɪs/ n. 阴茎
A149: 148 | B149: Br. | C149: Br. is a written abbreviation for (书面缩略 =) British.
A150: 149 | B150: wit | C150: =VLOOKUP(B150,Sheet1!$A:$B,2,0) -> /wɪt//wɪt/ n. 智力；才智；智慧 时 态: wist witting first and third person singular present tense wot
A151: 150 | B151: lb | C151: =VLOOKUP(B151,Sheet1!$A:$B,2,0) -> abbr. 救生船（Lifeboat） lbabbr. Lebanon 黎巴嫩
A152: 151 | B152: psychology | C152: =VLOOKUP(B152,Sheet1!$A:$B,2,0) -> /saɪ'kɒlədʒɪ//saɪ'kɑlədʒi/ - n. 心理学 - 心理; 心理特点
A153: 152 | B153: cord | C153: =VLOOKUP(B153,Sheet1!$A:$B,2,0) -> /kɔːd//kɔrd/ - n. 束缚；绳索 - vt. 用绳子捆绑 时 态: corded, cording, cords 名 词: corder
A154: 153 | B154: Feb. | C154: =VLOOKUP(B154,Sheet1!$A:$B,2,0) -> abbr. February 二月
A155: 154 | B155: rod | C155: =VLOOKUP(B155,Sheet1!$A:$B,2,0) -> /rɒd//rɑd/ n. 竿, 杆, 棒
A156: 155 | B156: accountable | C156: =VLOOKUP(B156,Sheet1!$A:$B,2,0) -> /ə'kaʊntəb(ə)l//ə'kaʊntəbl/ adj. 负有责任的, 应对自己的行为做出说明的 名 词: accountability or 副 词: accountably
A157: 156 | B157: batter | C157: =VLOOKUP(B157,Sheet1!$A:$B,2,0) -> /'bætə//'bætɚ/ - n. 击球手；（用鸡蛋、牛奶、面粉等调成的）糊状物；墙面的倾斜 - vt. 猛击；打坏；使向上倾斜 - vi. 接连猛击；向上倾斜 时 态: battered, battering, batters...
A158: 157 | B158: pro | C158: =VLOOKUP(B158,Sheet1!$A:$B,2,0) -> /prəʊ//pro/ - adv. 赞成地 - n. 赞成者；赞成的意见 - prep. 赞成 Pro脯氨酸 PROabbr. Public Record Office 档案局( PROabbr. Public Record Office 〈英〉档案局(
A159: 158 | B159: cynical | C159: =VLOOKUP(B159,Sheet1!$A:$B,2,0) -> /'sɪnɪk(ə)l//'sɪnɪkl/ adj. 愤世嫉俗的；冷嘲的 副 词: cynically 名 词: cynicalness
A160: 159 | B160: paradise | C160: =VLOOKUP(B160,Sheet1!$A:$B,2,0) -> /'pærədaɪs//'pærə'daɪs/ n. 天堂 形容词: paradisiacal 副 词: paradisiacally or
A161: 160 | B161: tablet | C161: =VLOOKUP(B161,Sheet1!$A:$B,2,0) -> /'tæblɪt//'tæblət/ - n. 药片 - (木、竹)简; 碑, 牌匾 时 态: tableted, tableting, tablets
... A222: 221 | B222: nut | C222: =VLOOKUP(B222,Sheet1!$A:$B,2,0) -> /nʌt//nʌt/ - n. 干果, 坚果 - 螺母, 螺帽 - 头 NUTabbr. National Union of Teachers全国教师联合会 NUTabbr. National Union of Teachers 〈英〉全国教师联合会 时 态: nutted, nutting, nuts 名 词: nutter...
A223: 222 | B223: carbon dioxide | C223: N-UNCOUNT 不可数名词 二氧化碳
A224: 223 | B224: clip | C224: =VLOOKUP(B224,Sheet1!$A:$B,2,0) -> /klɪp//klɪp/ - vt. 修剪；夹牢；痛打 - vi. 修剪 - n. 夹子；修剪；回形针 CLIP - abbr. Cellular Logic Image Processor 单元逻辑映象处理器 - Compiler Language for Information Processing 信息处理用的编译程序语言 - Computer Layout Installation Planner 计算机布局安装规划程序 时 态: clipped, clipping, clips...
A225: 224 | B225: gardener | C225: =VLOOKUP(B225,Sheet1!$A:$B,2,0) -> /'ɡɑːdənə//'gɑrdənɚ/ n. 花匠；园丁；园艺家
A226: 225 | B226: bait | C226: =VLOOKUP(B226,Sheet1!$A:$B,2,0) -> /beɪt//bet/ - n. (钓鱼等用的)饵, 诱饵 - vt. 装饵于 - 故意激怒 时 态: baited, baiting, baits 名 词: baiter
A227: 226 | B227: attendant | C227: =VLOOKUP(B227,Sheet1!$A:$B,2,0) -> /ə'tend(ə)nt//ə'tɛndənt/ - n. 服务人员, 侍者, 随从 - 伴随物 - adj. 伴随的, 随之而产生的 - 护理的 副 词: attendantly
A228: 227 | B228: hurricane | C228: =VLOOKUP(B228,Sheet1!$A:$B,2,0) -> /'hʌrɪk(ə)n//'hɝəkən/ n. 飓风, (尤指西印度群岛的)旋风
A229: 228 | B229: sprinkle | C229: =VLOOKUP(B229,Sheet1!$A:$B,2,0) -> /'sprɪŋk(ə)l//'sprɪŋkl/ - n. 少量；撒，洒 - vt. 洒；微雨；散置 - vi. 洒，撒；下稀疏小雨；喷撒 时 态: sprinkled, sprinkling, sprinkles
A230: 229 | B230: scoop | C230: =VLOOKUP(B230,Sheet1!$A:$B,2,0) -> /skuːp//skup/ - n. 小铲; 小勺 - 一勺[铲]之量 - (抢先刊载、播出的)独家新闻 - vt. 用铲[勺]等挖(洞等) - 抢先报道 - 抢先获得, 胜过 时 态: scooped, scooping, scoops 名 词: scooper 名 词: scoopful...
A231: 230 | B231: relaxed | C231: =VLOOKUP(B231,Sheet1!$A:$B,2,0) -> /rɪˈlækst//rɪ'lækst/ - adj. 松懈的，放松的；不严格的，不拘束的；悠闲的，自在的 - v. relax的过去式和过去分词
A232: 231 | B232: hull | C232: =VLOOKUP(B232,Sheet1!$A:$B,2,0) -> /hʌl//hʌl/ - n. 船体, 船身 - vt. 去(谷物、豆等的)壳 Hull赫尔(①姓氏 ②Cordell, 1871 -1955, 美国政治家, 于1933 -1944任美国国务卿, 曾获1945年诺贝尔和平奖 ③英格兰东北部一港市 ④加拿大东南部一城市) 时 态: hulled, hulling, hulls 名 词: huller...
A233: 232 | B233: two-thirds | C233: QUANT 数量词 三分之二
A234: 233 | B234: petty | C234: =VLOOKUP(B234,Sheet1!$A:$B,2,0) -> /ˈpeti//ˈpɛti/ adj. 小规模的；小气的；琐碎的 Petty佩蒂(姓氏) 比较级: pettier, pettiest 副 词: pettily 名 词: pettiness
...

Sheet Sheet1
A1: appal | B1: /ə'pɔːl//əˈpɔl/ vt. 使惊骇; 使充满恐惧
A2: contractor | B2: /kən'træktə//kən'træktɚ/ n. (建筑、监造中的)承包人
A3: spectacle | B3: /'spektək(ə)l//'spɛktəkl/ - n. 壮观的场面或景象 - 可笑的事物; 愚蠢的景象 - 眼镜
A4: apt | B4: /æpt//æpt/ - adj. 易于…的, 有…倾向的 - 恰当的, 适宜的 - 聪明的, 灵巧的 APTabbr. Advanced Passenger Train高级旅客列车 副 词: aptly 名 词: aptness
A5: reactor | B5: /rɪ'æktə//rɪ'æktɚ/ n. 反应堆；反应器；起反应的人
A6: old-fashioned | B6: /'əuld'fæʃənd//ˈoldˈfæʃənd/ adj. 老式的,过时的,守旧的
A7: thief | B7: /θiːf//θif/ n. 小偷，贼
A8: snatch | B8: /snætʃ//snætʃ/ - n. 抢夺；小量；抓举 - vt. 夺得；抽空做；及时救助 - vi. 抢走；很快接受 时 态: snatched, snatching, snatches 名 词: snatcher
A9: mathematical | B9: /mæθ(ə)'mætɪk(ə)l//ˌmæθə'mætɪkl/ - adj. 数学的, 数学上的 - 精确的 副 词: mathematically
A10: technician | B10: /tek'nɪʃ(ə)n//tɛk'nɪʃən/ n. 技术人员, 专家; 技巧好的人
A11: groove | B11: /gruːv//ɡruv/ - n. 凹槽，槽；最佳状态；惯例 - vt. 开槽于 - vi. 形成沟槽 时 态: grooved, grooving, grooves
A12: gloom | B12: /gluːm//ɡlum/ - n. 昏暗, 阴暗 - 忧郁, 沮丧, 失望 时 态: gloomed, glooming, glooms
... A2075: insult | B2075: /ɪn'sʌlt//ɪn'sʌlt/ - vt. 侮辱, 冒犯 - n. 侮辱, 辱骂, 侮辱性的言论 时 态: insulted, insulting, insults 名 词: insulter 副 词: insultingly
A2076: j礖_x0014_0 ★★☆☆☆20.lrc&U_x0005__x0005__x0006__x0006_@_x0006_20.lrc袄ot[ti:单词风暴语音文件(★★☆☆☆20)
A2077: sue | B2077: /s(j)uː//su/ vt. & vi. (为要求赔偿损失而)起诉, 控告, 和…打官司 时 态: sued, suing, sues 名 词: suer
A2078: doubtful | B2078: /'daʊtfʊl//'daʊtfəl/ - adj. 难以预测的, 未定的 - 怀疑的, 可疑的 副 词: doubtfully 名 词: doubtfulness
A2079: underway | B2079: /'ʌndə'weɪ//ˌʌndɚ'we/ adj. 在进行中的
A2080: prone | B2080: /prəʊn//pron/ - adj. 易于…的; 很可能…的 - 俯卧的 副 词: pronely 名 词: proneness
A2081: brokerage | B2081: /'brəʊk(ə)rɪdʒ//'brokərɪdʒ/ - n. 经纪业 - 佣金,手续费,经纪费
A2082: brutal | B2082: /'bruːt(ə)l//'brutl/ adj. 残忍的；野蛮的，不讲理的 副 词: brutally
A2083: lifetime | B2083: /'laɪftaɪm//'laɪftaɪm/ - n. 一生；寿命；终生；使用期 - adj. 一生的；终身的
A2084: dense | B2084: /dens//dɛns/ adj. 浓厚的；稠密的；愚钝的 比较级: denser, densest 副 词: densely 名 词: denseness
A2085: exit | B2085: /'eksɪt//'ɛɡzɪt/ - n. 出口, 通道, 安全门 - 退出, 退场 - vi. 离开; 退场 时 态: exited, exiting, exits
A2086: asthma | B2086: /'æsmə//'æzmə/ n. 〈医〉气喘; 哮喘 形容词: asthmatic 副 词: asthmatically
A2087: sunlight | B2087: /'sʌnlaɪt//'sʌnlaɪt/ n. 日光
A2088: quarrel | B2088: /'kwɒr(ə)l//'kwɔrəl/ - n. 争吵, 不和, 口角 - 抱怨…的原因[理由] - vi. 争吵, 争辩 - 不同意; 挑剔 时 态: quarreled, quarrelled quarreling, quarrelling quarrels, quarrels 名 词: quarreler or...
... A2818: singing | B2818: /ˈsɪŋɪŋ//'sɪŋɪŋ/ - n. 歌声；歌唱；耳鸣；振鸣 - adj. 唱歌的；音乐般的 - v. 唱歌（sing的ing形式）
A2819: caf??
A2820: misleading | B2820: /mɪsˈli:dɪŋ//ˌmɪs'lidɪŋ/ adj. 欺骗的;误导性的 副 词: misleadingly
A2821: hopefully | B2821: /'həʊpfʊlɪ//'hopfəli/ adv. 怀有希望地;如果顺利的话,可望
A2822: corridor | B2822: /'kɒrɪdɔː//'kɔrɪdɔr/ n. 走廊
A2823: hound | B2823: /haʊnd//haʊnd/ - vt. 追猎；烦扰；激励 - n. 猎犬；卑劣的人 时 态: hounded, hounding, hounds 名 词: hounder
A2824: limp | B2824: /lɪmp//lɪmp/ - n. 跛行 - vi. 一瘸一拐地走 - 困难地航行 - adj. 无力的; 无生气的; 易弯的; 松软的 LIMPabbr. Language-Independent Macro Processor 独立于语言的宏加工程序 时 态: limped, limping, limps 副 词: limply 名 词: limpness...
A2825: bureaucrat | B2825: /'bjʊərəkræt//'bjʊrəkræt/ - n. 官僚,官僚主义者,官僚作风的人 - n. 官僚语言 - n. 官僚主义 - n. 官僚主义者 形容词: bureaucratic 副 词: bureaucratically...
A2826: conversion | B2826: /kən'vɜːʃ(ə)n//kən'vɝʒn/ - n. 变换, 转化 - (宗教、信仰等)彻底改变; 皈依 形容词: conversional or
A2827: journalism | B2827: /'dʒɜːn(ə)lɪz(ə)m//'dʒɝnl'ɪzəm/ n. 新闻业
A2828: slap | B2828: /slæp//slæp/ - vt. 掌击；拍击；掴…的耳光；侮辱 - n. 掌击；掴；侮辱；拍打声 - vi. 掴；拍击 - adv. 直接地；猛然地；恰好 时 态: slapped, slapping, slaps 名 词: slapper...
A2829: impatient | B2829: /ɪm'peɪʃ(ə)nt//ɪm'peʃnt/ - adj. 不耐烦的, 急躁的 - 热切的, 急切的 副 词: impatiently
A2830: continuous | B2830: /kən'tɪnjʊəs//kən'tɪnjʊəs/ adj. 连续的, 没有中断的 副 词: continuously 名 词: continuousness
A2831: imposing | B2831: /ɪm'pəʊzɪŋ//ɪm'pozɪŋ/ adj. 庄严的, 仪表堂堂的, 令人印象深刻的 副 词: imposingly
...

Sheet sheet2
A1: appal | B1: v.惊骇
A2: oust | B2: vt.剥夺, 取代, 驱逐
A3: purse | B3: n.钱包
A4: glare | B4: n.眩目的光, 显眼, 怒目而视, (冰等的表面)光滑的表面
A5: hobby | B5: n.业余爱好
A6: excellence | B6: n.优秀, 卓越, 优点, 美德
A7: contractor | B7: n.订约人, 承包人
A8: format | B8: n.开本, 版式, 形式, 格式
A9: gloom | B9: n.阴暗, 阴沉
A10: constituent | B10: n.委托人, 要素
A11: reactor | B11: n.反应堆
A12: ass | B12: n.驴, 笨人, 臀部
... A2047: FBI | B2047: FBI
A2048: j礖_x0014_0 ★★☆☆☆20.lrc&U_x0005__x0005__x0006__x0006_@_x0006_20.lrc袄ot[ti:单词风暴语音文件(★★☆☆☆20)
A2049: hover | B2049: vi. 盘旋，翱翔；徘徊 n. 徘徊；盘旋；犹豫 vt. 孵；徘徊在…近旁
A2050: glove | B2050: n.手套
A2051: team-mate | B2051: team-mate
A2052: brick | B2052: n.砖, 砖块, 砖形物(如茶砖,冰砖等), <口>心肠好的人
A2053: compose | B2053: v.组成, 写作, 排字, (使)安定, 调解
A2054: ooh | B2054: int. （表示惊讶、欣喜、痛苦等）嚯，呵
A2055: sunlight | B2055: n.日光, 阳光, 日照
A2056: power station | B2056: n.发电所
A2057: asthma | B2057: n.〖医〗哮喘
A2058: surgical | B2058: adj.外科的, 外科医生的, 手术上的
A2059: spine | B2059: n.脊骨, 书脊, 地面隆起地带, 中心, 剌
A2060: custom | B2060: n.习惯, 风俗, <动词单用>海关, (封建制度下)定期服劳役, 缴纳租税, 自定义, <偶用作>关税
... A3048: contradiction | B3048: n.反驳, 矛盾
